<?xml version="1.0" ?>
<mujoco model="Quadcopter">
   <compiler angle="degree" coordinate="local" inertiafromgeom="true"/>
   <worldbody>
      <geom name="ground" type="plane" size="2 2 0.02" friction="1.0" pos="0.0 0.0 0.0" rgba="0.8 0.9 0.8 1.0"/>
      <body name="quadrotor" pos="0.0 0.0 1.0" quat="1 0 0 0">
         <geom name="geom" type="box" pos="0.0 0.0 0.0" quat="1 0 0 0" size="0.08 0.04 0.025" mass="0.75" density="1000" rgba="0.3 0.3 0.8 1.0"/>
         <joint name="root_joint" type="free" limited="false" pos="0.0 0.0 0.0" axis="0.0 0.0 1.0" range="-1.0 1.0" damping="0.1" stiffness="0.0" armature="0.0"/>
         <geom name="rotor_arm_geom_0" type="box" pos="0.0 0.0 0.0" quat="0.92388 0 0 0.382683" size="0.2 0.01 0.01" mass="0.01" density="1000" rgba="0.1 0.1 0.5 1.0"/>
         <body name="rotor_prop_0" pos="0.1414213562373095 0.14142135623730953 0.0" quat="1 0 0 0">
            <joint name="rotor_joint_0" type="hinge" limited="true" pos="0.1414213562373095 0.14142135623730953 0.0" axis="0.0 1.0 0.0" range="-0.001 0.001" damping="1000" stiffness="10000" armature="0.0"/>
            <geom name="rotor_prop_geom_0" type="cylinder" size="0.1 0.005" pos="0.0 0.0 0.0" mass="0.05" density="1000" rgba="0.5 0.1 0.1 1.0"/>
         </body>
         <geom name="rotor_arm_geom_1" type="box" pos="0.0 0.0 0.0" quat="0.382683 0 0 0.92388" size="0.2 0.01 0.01" mass="0.01" density="1000" rgba="0.1 0.1 0.5 1.0"/>
         <body name="rotor_prop_1" pos="-0.1414213562373095 0.14142135623730953 0.0" quat="1 0 0 0">
            <joint name="rotor_joint_1" type="hinge" limited="true" pos="-0.1414213562373095 0.14142135623730953 0.0" axis="0.0 1.0 0.0" range="-0.001 0.001" damping="1000" stiffness="10000" armature="0.0"/>
            <geom name="rotor_prop_geom_1" type="cylinder" size="0.1 0.005" pos="0.0 0.0 0.0" mass="0.05" density="1000" rgba="0.5 0.1 0.1 1.0"/>
         </body>
         <geom name="rotor_arm_geom_2" type="box" pos="0.0 0.0 0.0" quat="-0.382683 0 0 0.92388" size="0.2 0.01 0.01" mass="0.01" density="1000" rgba="0.1 0.1 0.5 1.0"/>
         <body name="rotor_prop_2" pos="-0.1414213562373095 -0.1414213562373095 0.0" quat="1 0 0 0">
            <joint name="rotor_joint_2" type="hinge" limited="true" pos="-0.1414213562373095 -0.1414213562373095 0.0" axis="0.0 1.0 0.0" range="-0.001 0.001" damping="1000" stiffness="10000" armature="0.0"/>
            <geom name="rotor_prop_geom_2" type="cylinder" size="0.1 0.005" pos="0.0 0.0 0.0" mass="0.05" density="1000" rgba="0.5 0.1 0.1 1.0"/>
         </body>
         <geom name="rotor_arm_geom_3" type="box" pos="0.0 0.0 0.0" quat="-0.92388 0 0 0.382683" size="0.2 0.01 0.01" mass="0.01" density="1000" rgba="0.1 0.1 0.5 1.0"/>
         <body name="rotor_prop_3" pos="0.14142135623730948 -0.14142135623730956 0.0" quat="1 0 0 0">
            <joint name="rotor_joint_3" type="hinge" limited="true" pos="0.14142135623730948 -0.14142135623730956 0.0" axis="0.0 1.0 0.0" range="-0.001 0.001" damping="1000" stiffness="10000" armature="0.0"/>
            <geom name="rotor_prop_geom_3" type="cylinder" size="0.1 0.005" pos="0.0 0.0 0.0" mass="0.05" density="1000" rgba="0.5 0.1 0.1 1.0"/>
         </body>
      </body>
   </worldbody>
</mujoco>
