<?xml version="1.0"?>
<mujoco model="QuadFlexibleCablePayload">
  <include file="scene.xml" />
  <compiler angle="degree" coordinate="local" inertiafromgeom="true" />
  <asset>
    <texture type="skybox" builtin="gradient" rgb1="1.0 1.0 1.0" rgb2="0.6 0.8 1.0" width="256"
      height="256" />
  </asset>
  <worldbody>
    <geom name="ground" type="plane" size="5.0 5.0 0.02" friction="1.0" pos="0.0 0.0 0.0"
      rgba="0.8 0.9 0.8 1.0" />
    <light directional="true" diffuse=".9 .9 .9" specular=".3 .3 .3" pos="0 0 4.0" dir="0 0.15 -1" />
    <body name="quadrotor" pos="0.0 0.0 2.0" quat="1 0 0 0">
      <geom name="quadrotor_geom" type="box" pos="0.0 0.0 0.0" quat="1 0 0 0" size="0.08 0.04 0.025"
        mass="0.75" density="1000" rgba="0.3 0.3 0.8 1.0" />
      <joint name="quadrotor_root_joint" type="free" />
      <geom name="quadrotor_rotor_arm_geom_0" type="box" pos="0.0 0.0 0.0"
        quat="0.92388 0 0 0.382683" size="0.2 0.01 0.01" mass="0.01" density="1000"
        rgba="0.1 0.1 0.5 1.0" />
      <geom name="quadrotor_rotor_prop_geom_0" type="cylinder" size="0.1 0.005"
        pos="0.1414213562373095 0.14142135623730953 0.0" mass="0.05" density="1000"
        rgba="0.5 0.1 0.1 1.0" />
      <geom name="quadrotor_rotor_arm_geom_1" type="box" pos="0.0 0.0 0.0"
        quat="0.382683 0 0 0.92388" size="0.2 0.01 0.01" mass="0.01" density="1000"
        rgba="0.1 0.1 0.5 1.0" />
      <geom name="quadrotor_rotor_prop_geom_1" type="cylinder" size="0.1 0.005"
        pos="-0.1414213562373095 0.14142135623730953 0.0" mass="0.05" density="1000"
        rgba="0.5 0.1 0.1 1.0" />
      <geom name="quadrotor_rotor_arm_geom_2" type="box" pos="0.0 0.0 0.0"
        quat="-0.382683 0 0 0.92388" size="0.2 0.01 0.01" mass="0.01" density="1000"
        rgba="0.1 0.1 0.5 1.0" />
      <geom name="quadrotor_rotor_prop_geom_2" type="cylinder" size="0.1 0.005"
        pos="-0.1414213562373095 -0.1414213562373095 0.0" mass="0.05" density="1000"
        rgba="0.5 0.1 0.1 1.0" />
      <geom name="quadrotor_rotor_arm_geom_3" type="box" pos="0.0 0.0 0.0"
        quat="-0.92388 0 0 0.382683" size="0.2 0.01 0.01" mass="0.01" density="1000"
        rgba="0.1 0.1 0.5 1.0" />
      <geom name="quadrotor_rotor_prop_geom_3" type="cylinder" size="0.1 0.005"
        pos="0.14142135623730948 -0.14142135623730956 0.0" mass="0.05" density="1000"
        rgba="0.5 0.1 0.1 1.0" />
      <site name="quadrotor_end1" type="sphere" pos="0.0 0.0 0.0" quat="1 0 0 0" size="0.01"
        rgba="0.1 0.1 0.5 1.0" />
      <site name="site0" type="box" pos="0.1414213562373095 0.14142135623730953 0.0" quat="1 0 0 0"
        size="0.01 0.01 0.01" rgba="0.0 1 1 1.0" />
      <site name="site1" type="box" pos="-0.1414213562373095 0.14142135623730953 0.0" quat="1 0 0 0"
        size="0.01 0.01 0.01" rgba="0.0 1 1 1.0" />
      <site name="site2" type="box" pos="-0.1414213562373095 -0.1414213562373095 0.0" quat="1 0 0 0"
        size="0.01 0.01 0.01" rgba="0.0 1 1 1.0" />
      <site name="site3" type="box" pos="0.14142135623730948 -0.14142135623730956 0.0"
        quat="1 0 0 0" size="0.01 0.01 0.01" rgba="0.0 1 1 1.0" />
      <site name="quadrotor_thrust" type="box" pos="0.0 0.0 0.0" quat="1 0 0 0"
        size="0.035 0.035 0.035" rgba="0.0 1 1 1.0" />
      <site name="quadrotor_Mx" type="box" pos="0.0 0.0 0.0" quat="1 0 0 0" size="0.06 0.035 0.025"
        rgba="0.0 1 1 1.0" />
      <site name="quadrotor_My" type="box" pos="0.0 0.0 0.0" quat="1 0 0 0" size="0.06 0.035 0.025"
        rgba="0.0 1 1 1.0" />
      <site name="quadrotor_Mz" type="box" pos="0.0 0.0 0.0" quat="1 0 0 0" size="0.06 0.035 0.025"
        rgba="0.0 1 1 1.0" />
      <body name="cable_0" pos="0.0 0.0 -0.02" quat="1 0 0 0">
        <joint name="cable_quad_joint_0" type="ball" limited="false" pos="0.0 0.0 0.02"
          damping="0.0001" stiffness="0" />
        <geom name="cable_cylinder_0" type="cylinder" size="0.01 0.02" pos="0.0 0.0 0.0"
          mass="0.0004" density="50" rgba="0.2 0.2 0.2 1.0" />
        <body name="cable_1" pos="0.0 0.0 -0.04" quat="1 0 0 0">
          <joint name="cable_quad_joint_1" type="ball" limited="false" pos="0.0 0.0 0.02"
            damping="0.001" stiffness="0.0" />
          <geom name="cable_cylinder_1" type="cylinder" size="0.0015 0.02" pos="0.0 0.0 0.0"
            mass="0.0004" density="50" rgba="0.2 0.2 0.2 1.0" />
          <body name="cable_2" pos="0.0 0.0 -0.04" quat="1 0 0 0">
            <joint name="cable_quad_joint_2" type="ball" limited="false" pos="0.0 0.0 0.02"
              damping="0.001" stiffness="0.0" />
            <geom name="cable_cylinder_2" type="cylinder" size="0.0015 0.02" pos="0.0 0.0 0.0"
              mass="0.0004" density="50" rgba="0.2 0.2 0.2 1.0" />
            <body name="cable_3" pos="0.0 0.0 -0.04" quat="1 0 0 0">
              <joint name="cable_quad_joint_3" type="ball" limited="false" pos="0.0 0.0 0.02"
                damping="0.001" stiffness="0.0" />
              <geom name="cable_cylinder_3" type="cylinder" size="0.0015 0.02" pos="0.0 0.0 0.0"
                mass="0.0004" density="50" rgba="0.2 0.2 0.2 1.0" />
              <body name="cable_4" pos="0.0 0.0 -0.04" quat="1 0 0 0">
                <joint name="cable_quad_joint_4" type="ball" limited="false" pos="0.0 0.0 0.02"
                  damping="0.001" stiffness="0.0" />
                <geom name="cable_cylinder_4" type="cylinder" size="0.0015 0.02" pos="0.0 0.0 0.0"
                  mass="0.0004" density="50" rgba="0.2 0.2 0.2 1.0" />
                <body name="cable_5" pos="0.0 0.0 -0.04" quat="1 0 0 0">
                  <joint name="cable_quad_joint_5" type="ball" limited="false" pos="0.0 0.0 0.02"
                    damping="0.001" stiffness="0.0" />
                  <geom name="cable_cylinder_5" type="cylinder" size="0.0015 0.02" pos="0.0 0.0 0.0"
                    mass="0.0004" density="50" rgba="0.2 0.2 0.2 1.0" />
                  <body name="cable_6" pos="0.0 0.0 -0.04" quat="1 0 0 0">
                    <joint name="cable_quad_joint_6" type="ball" limited="false" pos="0.0 0.0 0.02"
                      damping="0.001" stiffness="0.0" />
                    <geom name="cable_cylinder_6" type="cylinder" size="0.0015 0.02"
                      pos="0.0 0.0 0.0" mass="0.0004" density="50" rgba="0.2 0.2 0.2 1.0" />
                    <body name="cable_7" pos="0.0 0.0 -0.04" quat="1 0 0 0">
                      <joint name="cable_quad_joint_7" type="ball" limited="false"
                        pos="0.0 0.0 0.02" damping="0.001" stiffness="0.0" />
                      <geom name="cable_cylinder_7" type="cylinder" size="0.0015 0.02"
                        pos="0.0 0.0 0.0" mass="0.0004" density="50" rgba="0.2 0.2 0.2 1.0" />
                      <body name="cable_8" pos="0.0 0.0 -0.04" quat="1 0 0 0">
                        <joint name="cable_quad_joint_8" type="ball" limited="false"
                          pos="0.0 0.0 0.02" damping="0.001" stiffness="0.0" />
                        <geom name="cable_cylinder_8" type="cylinder" size="0.0015 0.02"
                          pos="0.0 0.0 0.0" mass="0.0004" density="50" rgba="0.2 0.2 0.2 1.0" />
                        <body name="cable_9" pos="0.0 0.0 -0.04" quat="1 0 0 0">
                          <joint name="cable_quad_joint_9" type="ball" limited="false"
                            pos="0.0 0.0 0.02" damping="0.001" stiffness="0.0" />
                          <geom name="cable_cylinder_9" type="cylinder" size="0.0015 0.02"
                            pos="0.0 0.0 0.0" mass="0.0004" density="50" rgba="0.2 0.2 0.2 1.0" />
                          <body name="cable_10" pos="0.0 0.0 -0.04" quat="1 0 0 0">
                            <joint name="cable_quad_joint_10" type="ball" limited="false"
                              pos="0.0 0.0 0.02" damping="0.001" stiffness="0.0" />
                            <geom name="cable_cylinder_10" type="cylinder" size="0.0015 0.02"
                              pos="0.0 0.0 0.0" mass="0.0004" density="50" rgba="0.2 0.2 0.2 1.0" />
                            <body name="cable_11" pos="0.0 0.0 -0.04" quat="1 0 0 0">
                              <joint name="cable_quad_joint_11" type="ball" limited="false"
                                pos="0.0 0.0 0.02" damping="0.001" stiffness="0.0" />
                              <geom name="cable_cylinder_11" type="cylinder" size="0.0015 0.02"
                                pos="0.0 0.0 0.0" mass="0.0004" density="50" rgba="0.2 0.2 0.2 1.0" />
                              <body name="cable_12" pos="0.0 0.0 -0.04" quat="1 0 0 0">
                                <joint name="cable_quad_joint_12" type="ball" limited="false"
                                  pos="0.0 0.0 0.02" damping="0.001" stiffness="0.0" />
                                <geom name="cable_cylinder_12" type="cylinder" size="0.0015 0.02"
                                  pos="0.0 0.0 0.0" mass="0.0004" density="50"
                                  rgba="0.2 0.2 0.2 1.0" />
                                <body name="cable_13" pos="0.0 0.0 -0.04" quat="1 0 0 0">
                                  <joint name="cable_quad_joint_13" type="ball" limited="false"
                                    pos="0.0 0.0 0.02" damping="0.001" stiffness="0.0" />
                                  <geom name="cable_cylinder_13" type="cylinder" size="0.0015 0.02"
                                    pos="0.0 0.0 0.0" mass="0.0004" density="50"
                                    rgba="0.2 0.2 0.2 1.0" />
                                  <body name="cable_14" pos="0.0 0.0 -0.04" quat="1 0 0 0">
                                    <joint name="cable_quad_joint_14" type="ball" limited="false"
                                      pos="0.0 0.0 0.02" damping="0.001" stiffness="0.0" />
                                    <geom name="cable_cylinder_14" type="cylinder"
                                      size="0.0015 0.02" pos="0.0 0.0 0.0" mass="0.0004"
                                      density="50" rgba="0.2 0.2 0.2 1.0" />
                                    <body name="cable_15" pos="0.0 0.0 -0.04" quat="1 0 0 0">
                                      <joint name="cable_quad_joint_15" type="ball" limited="false"
                                        pos="0.0 0.0 0.02" damping="0.001" stiffness="0.0" />
                                      <geom name="cable_cylinder_15" type="cylinder"
                                        size="0.0015 0.02" pos="0.0 0.0 0.0" mass="0.0004"
                                        density="50" rgba="0.2 0.2 0.2 1.0" />
                                      <body name="cable_16" pos="0.0 0.0 -0.04" quat="1 0 0 0">
                                        <joint name="cable_quad_joint_16" type="ball"
                                          limited="false" pos="0.0 0.0 0.02" damping="0.001"
                                          stiffness="0.0" />
                                        <geom name="cable_cylinder_16" type="cylinder"
                                          size="0.0015 0.02" pos="0.0 0.0 0.0" mass="0.0004"
                                          density="50" rgba="0.2 0.2 0.2 1.0" />
                                        <body name="cable_17" pos="0.0 0.0 -0.04" quat="1 0 0 0">
                                          <joint name="cable_quad_joint_17" type="ball"
                                            limited="false" pos="0.0 0.0 0.02" damping="0.001"
                                            stiffness="0.0" />
                                          <geom name="cable_cylinder_17" type="cylinder"
                                            size="0.0015 0.02" pos="0.0 0.0 0.0" mass="0.0004"
                                            density="50" rgba="0.2 0.2 0.2 1.0" />
                                          <body name="cable_18" pos="0.0 0.0 -0.04" quat="1 0 0 0">
                                            <joint name="cable_quad_joint_18" type="ball"
                                              limited="false" pos="0.0 0.0 0.02" damping="0.001"
                                              stiffness="0.0" />
                                            <geom name="cable_cylinder_18" type="cylinder"
                                              size="0.0015 0.02" pos="0.0 0.0 0.0" mass="0.0004"
                                              density="50" rgba="0.2 0.2 0.2 1.0" />
                                            <body name="cable_19" pos="0.0 0.0 -0.04" quat="1 0 0 0">
                                              <joint name="cable_quad_joint_19" type="ball"
                                                limited="false" pos="0.0 0.0 0.02" damping="0.001"
                                                stiffness="0.0" />
                                              <geom name="cable_cylinder_19" type="cylinder"
                                                size="0.0015 0.02" pos="0.0 0.0 0.0" mass="0.0004"
                                                density="50" rgba="0.2 0.2 0.2 1.0" />
                                              <body name="cable_20" pos="0.0 0.0 -0.04"
                                                quat="1 0 0 0">
                                                <joint name="cable_quad_joint_20" type="ball"
                                                  limited="false" pos="0.0 0.0 0.02" damping="0.001"
                                                  stiffness="0.0" />
                                                <geom name="cable_cylinder_20" type="cylinder"
                                                  size="0.0015 0.02" pos="0.0 0.0 0.0" mass="0.0004"
                                                  density="50" rgba="0.2 0.2 0.2 1.0" />
                                                <body name="cable_21" pos="0.0 0.0 -0.04"
                                                  quat="1 0 0 0">
                                                  <joint name="cable_quad_joint_21" type="ball"
                                                    limited="false" pos="0.0 0.0 0.02"
                                                    damping="0.001" stiffness="0.0" />
                                                  <geom name="cable_cylinder_21" type="cylinder"
                                                    size="0.0015 0.02" pos="0.0 0.0 0.0"
                                                    mass="0.0004" density="50"
                                                    rgba="0.2 0.2 0.2 1.0" />
                                                  <body name="cable_22" pos="0.0 0.0 -0.04"
                                                    quat="1 0 0 0">
                                                    <joint name="cable_quad_joint_22" type="ball"
                                                      limited="false" pos="0.0 0.0 0.02"
                                                      damping="0.001" stiffness="0.0" />
                                                    <geom name="cable_cylinder_22" type="cylinder"
                                                      size="0.0015 0.02" pos="0.0 0.0 0.0"
                                                      mass="0.0004" density="50"
                                                      rgba="0.2 0.2 0.2 1.0" />
                                                    <body name="cable_23" pos="0.0 0.0 -0.04"
                                                      quat="1 0 0 0">
                                                      <joint name="cable_quad_joint_23" type="ball"
                                                        limited="false" pos="0.0 0.0 0.02"
                                                        damping="0.001" stiffness="0.0" />
                                                      <geom name="cable_cylinder_23" type="cylinder"
                                                        size="0.0015 0.02" pos="0.0 0.0 0.0"
                                                        mass="0.0004" density="50"
                                                        rgba="0.2 0.2 0.2 1.0" />
                                                      <body name="cable_24" pos="0.0 0.0 -0.04"
                                                        quat="1 0 0 0">
                                                        <joint name="cable_quad_joint_24"
                                                          type="ball" limited="false"
                                                          pos="0.0 0.0 0.02" damping="0.001"
                                                          stiffness="0.0" />
                                                        <geom name="cable_cylinder_24"
                                                          type="cylinder" size="0.0015 0.02"
                                                          pos="0.0 0.0 0.0" mass="0.0004"
                                                          density="50" rgba="0.2 0.2 0.2 1.0" />
                                                        <body name="pyld" pos="0.0 0.0 -0.045"
                                                          quat="1 0 0 0">
                                                          <geom name="pyld" type="box"
                                                            pos="0.0 0.0 0.0" quat="1 0 0 0"
                                                            size="0.05 0.05 0.025" mass="0.15"
                                                            density="1" rgba="0.0 0.8 0.2 1.0" />
                                                          <joint name="pyld_joint" type="ball"
                                                            limited="false" pos="0.0 0.0 0.0"
                                                            damping="0" stiffness="0.0" />
                                                        </body>
                                                      </body>
                                                    </body>
                                                  </body>
                                                </body>
                                              </body>
                                            </body>
                                          </body>
                                        </body>
                                      </body>
                                    </body>
                                  </body>
                                </body>
                              </body>
                            </body>
                          </body>
                        </body>
                      </body>
                    </body>
                  </body>
                </body>
              </body>
            </body>
          </body>
        </body>
      </body>
    </body>
  </worldbody>
  <actuator>
    <motor ctrllimited="true" site="site0" ctrlrange="0.0 10.0"
      gear="0. 0. 1. 0. 0. -.024994577607878814" /> # each propeller can generate a force of 10N <motor
      ctrllimited="true" site="site1" ctrlrange="0.0 10.0" gear="0. 0. 1. 0. 0. .024994577607878814" />
     <motor
      ctrllimited="true" site="site2" ctrlrange="0.0 10.0"
      gear="0. 0. 1. 0. 0. -.024994577607878814" />
     <motor ctrllimited="true" site="site3"
      ctrlrange="0.0 10.0" gear="0. 0. 1. 0. 0. .024994577607878814" />
     <motor ctrllimited="true"
      site="quadrotor_thrust" ctrlrange="0.0 40.0" gear="0.0 0.0 1.0 0.0 0.0 0.0" />
     <motor
      ctrllimited="true" site="quadrotor_Mx" ctrlrange="-3.0 3.0" gear="0.0 0.0 0.0 1.0 0.0 0.0" />
     <motor
      ctrllimited="true" site="quadrotor_My" ctrlrange="-3.0 3.0" gear="0.0 0.0 0.0 0.0 1.0 0.0" />
     <motor
      ctrllimited="true" site="quadrotor_Mz" ctrlrange="-3.0 3.0" gear="0.0 0.0 0.0 0.0 0.0 1.0" />
  </actuator>
</mujoco>